Traceback (most recent call last):
  File "/usr/local/lib/python3.12/site-packages/jupyter_cache/executors/utils.py", line 58, in single_nb_execution
    executenb(
  File "/usr/local/lib/python3.12/site-packages/nbclient/client.py", line 1314, in execute
    return NotebookClient(nb=nb, resources=resources, km=km, **kwargs).execute()
           ^^^^^^^^^^^^^^^^^^^^^^^^^^^^^^^^^^^^^^^^^^^^^^^^^^^^^^^^^^^^^^^^^^^^^
  File "/usr/local/lib/python3.12/site-packages/jupyter_core/utils/__init__.py", line 165, in wrapped
    return loop.run_until_complete(inner)
           ^^^^^^^^^^^^^^^^^^^^^^^^^^^^^^
  File "/usr/local/Cellar/python@3.12/3.12.3/Frameworks/Python.framework/Versions/3.12/lib/python3.12/asyncio/base_events.py", line 687, in run_until_complete
    return future.result()
           ^^^^^^^^^^^^^^^
  File "/usr/local/lib/python3.12/site-packages/nbclient/client.py", line 709, in async_execute
    await self.async_execute_cell(
  File "/usr/local/lib/python3.12/site-packages/nbclient/client.py", line 1062, in async_execute_cell
    await self._check_raise_for_error(cell, cell_index, exec_reply)
  File "/usr/local/lib/python3.12/site-packages/nbclient/client.py", line 918, in _check_raise_for_error
    raise CellExecutionError.from_cell_and_msg(cell, exec_reply_content)
nbclient.exceptions.CellExecutionError: An error occurred while executing the following cell:
------------------
# Fonction de perte en classification
criterion = nn.CrossEntropyLoss() 
optimizer = torch.optim.Adam(model.parameters(), lr=0.02)

def precision(pred_y, y):
    return (pred_y == y).sum() / len(y)

pertes = []
precisions = []
res = []

nb_epohs = 300

for epoch in range(nb_epochs):
    # Clear gradients
    optimizer.zero_grad()

    _, z = model(data.x, data.edge_index)

    perte = criterion(z, data.y)

    p = precision(z.argmax(dim=1), data.y)

    perte.backward()
    optimizer.step()

    pertes.append(perte)
    precisions.append(p)
    res.append(z.argmax(dim=1))
------------------


[0;31m---------------------------------------------------------------------------[0m
[0;31mNameError[0m                                 Traceback (most recent call last)
Cell [0;32mIn[7], line 14[0m
[1;32m     10[0m res [38;5;241m=[39m []
[1;32m     12[0m nb_epohs [38;5;241m=[39m [38;5;241m300[39m
[0;32m---> 14[0m [38;5;28;01mfor[39;00m epoch [38;5;129;01min[39;00m [38;5;28mrange[39m([43mnb_epochs[49m):
[1;32m     15[0m     [38;5;66;03m# Clear gradients[39;00m
[1;32m     16[0m     optimizer[38;5;241m.[39mzero_grad()
[1;32m     18[0m     _, z [38;5;241m=[39m model(data[38;5;241m.[39mx, data[38;5;241m.[39medge_index)

[0;31mNameError[0m: name 'nb_epochs' is not defined

